<?xml version="1.0" ?>
<!-- =================================================================================== -->
<!-- |    This document was autogenerated by xacro from quadurdf.xacro                 | -->
<!-- |    EDITING THIS FILE BY HAND IS NOT RECOMMENDED                                 | -->
<!-- =================================================================================== -->
<robot name="quadurdf">
  <material name="silver_default">
    <color rgba="0.700 0.700 0.700 1.000"/>
  </material>
  <material name="steel_satin">
    <color rgba="0.6274509803921569 0.6274509803921569 0.6274509803921569 1.0"/>
  </material>
  <transmission name="Revolute 5_tran">
    <type>transmission_interface/SimpleTransmission</type>
    <joint name="Revolute 5">
      <hardwareInterface>hardware_interface/EffortJointInterface</hardwareInterface>
    </joint>
    <actuator name="Revolute 5_actr">
      <hardwareInterface>hardware_interface/EffortJointInterface</hardwareInterface>
      <mechanicalReduction>1</mechanicalReduction>
    </actuator>
  </transmission>
  <transmission name="Revolute 6_tran">
    <type>transmission_interface/SimpleTransmission</type>
    <joint name="Revolute 6">
      <hardwareInterface>hardware_interface/EffortJointInterface</hardwareInterface>
    </joint>
    <actuator name="Revolute 6_actr">
      <hardwareInterface>hardware_interface/EffortJointInterface</hardwareInterface>
      <mechanicalReduction>1</mechanicalReduction>
    </actuator>
  </transmission>
  <transmission name="Revolute 7_tran">
    <type>transmission_interface/SimpleTransmission</type>
    <joint name="Revolute 7">
      <hardwareInterface>hardware_interface/EffortJointInterface</hardwareInterface>
    </joint>
    <actuator name="Revolute 7_actr">
      <hardwareInterface>hardware_interface/EffortJointInterface</hardwareInterface>
      <mechanicalReduction>1</mechanicalReduction>
    </actuator>
  </transmission>
  <transmission name="Revolute 8_tran">
    <type>transmission_interface/SimpleTransmission</type>
    <joint name="Revolute 8">
      <hardwareInterface>hardware_interface/EffortJointInterface</hardwareInterface>
    </joint>
    <actuator name="Revolute 8_actr">
      <hardwareInterface>hardware_interface/EffortJointInterface</hardwareInterface>
      <mechanicalReduction>1</mechanicalReduction>
    </actuator>
  </transmission>
  <transmission name="Revolute 9_tran">
    <type>transmission_interface/SimpleTransmission</type>
    <joint name="Revolute 9">
      <hardwareInterface>hardware_interface/EffortJointInterface</hardwareInterface>
    </joint>
    <actuator name="Revolute 9_actr">
      <hardwareInterface>hardware_interface/EffortJointInterface</hardwareInterface>
      <mechanicalReduction>1</mechanicalReduction>
    </actuator>
  </transmission>
  <transmission name="Revolute 10_tran">
    <type>transmission_interface/SimpleTransmission</type>
    <joint name="Revolute 10">
      <hardwareInterface>hardware_interface/EffortJointInterface</hardwareInterface>
    </joint>
    <actuator name="Revolute 10_actr">
      <hardwareInterface>hardware_interface/EffortJointInterface</hardwareInterface>
      <mechanicalReduction>1</mechanicalReduction>
    </actuator>
  </transmission>
  <transmission name="Revolute 11_tran">
    <type>transmission_interface/SimpleTransmission</type>
    <joint name="Revolute 11">
      <hardwareInterface>hardware_interface/EffortJointInterface</hardwareInterface>
    </joint>
    <actuator name="Revolute 11_actr">
      <hardwareInterface>hardware_interface/EffortJointInterface</hardwareInterface>
      <mechanicalReduction>1</mechanicalReduction>
    </actuator>
  </transmission>
  <transmission name="Revolute 12_tran">
    <type>transmission_interface/SimpleTransmission</type>
    <joint name="Revolute 12">
      <hardwareInterface>hardware_interface/EffortJointInterface</hardwareInterface>
    </joint>
    <actuator name="Revolute 12_actr">
      <hardwareInterface>hardware_interface/EffortJointInterface</hardwareInterface>
      <mechanicalReduction>1</mechanicalReduction>
    </actuator>
  </transmission>
  <link name="base_link">
    <inertial>
      <origin rpy="0 0 0" xyz="-0.03749999999999933 -0.14809999999999918 0.03690650000000241"/>
      <mass value="1.0332661287911011"/>
      <inertia ixx="0.004001" ixy="-0.0" ixz="0.0" iyy="0.002008" iyz="-0.0" izz="0.006007"/>
    </inertial>
    <visual>
      <origin rpy="0 0 0" xyz="0 0 0"/>
      <geometry>
        <mesh filename="package://quadurdf_description/meshes/base_link.stl" scale="0.001 0.001 0.001"/>
      </geometry>
      <material name="steel_satin"/>
    </visual>
    <collision>
      <origin rpy="0 0 0" xyz="0 0 0"/>
      <geometry>
        <mesh filename="package://quadurdf_description/meshes/base_link.stl" scale="0.001 0.001 0.001"/>
      </geometry>
    </collision>
  </link>
  <link name="ACTUATOR_V2__HIP__v3_3">
    <inertial>
      <origin rpy="0 0 0" xyz="-0.038268337909519765 0.0023314411616331687 -0.03491102872215863"/>
      <mass value="5.047347679862185"/>
      <inertia ixx="0.004708" ixy="0.003872" ixz="1e-06" iyy="0.030025" iyz="1e-06" izz="0.030841"/>
    </inertial>
    <visual>
      <origin rpy="0 0 0" xyz="0.104 0.0822 -0.034907"/>
      <geometry>
        <mesh filename="package://quadurdf_description/meshes/ACTUATOR_V2__HIP__v3_3.stl" scale="0.001 0.001 0.001"/>
      </geometry>
      <material name="steel_satin"/>
    </visual>
    <collision>
      <origin rpy="0 0 0" xyz="0.104 0.0822 -0.034907"/>
      <geometry>
        <mesh filename="package://quadurdf_description/meshes/ACTUATOR_V2__HIP__v3_3.stl" scale="0.001 0.001 0.001"/>
      </geometry>
    </collision>
  </link>
  <link name="ACTUATOR_V2__HIP__v3_1">
    <inertial>
      <origin rpy="0 0 0" xyz="0.038268337909519765 -0.027668558838366546 -0.034902971277834656"/>
      <mass value="5.047347679862185"/>
      <inertia ixx="0.004708" ixy="-0.003872" ixz="1e-06" iyy="0.030025" iyz="-1e-06" izz="0.030841"/>
    </inertial>
    <visual>
      <origin rpy="0 0 0" xyz="-0.029 0.0522 -0.034907"/>
      <geometry>
        <mesh filename="package://quadurdf_description/meshes/ACTUATOR_V2__HIP__v3_1.stl" scale="0.001 0.001 0.001"/>
      </geometry>
      <material name="steel_satin"/>
    </visual>
    <collision>
      <origin rpy="0 0 0" xyz="-0.029 0.0522 -0.034907"/>
      <geometry>
        <mesh filename="package://quadurdf_description/meshes/ACTUATOR_V2__HIP__v3_1.stl" scale="0.001 0.001 0.001"/>
      </geometry>
    </collision>
  </link>
  <link name="ACTUATOR_V2__HIP__v3_4">
    <inertial>
      <origin rpy="0 0 0" xyz="-0.03826833790952035 -0.002331441161630504 -0.03490297127783731"/>
      <mass value="5.047347679862185"/>
      <inertia ixx="0.004708" ixy="-0.003872" ixz="-1e-06" iyy="0.030025" iyz="1e-06" izz="0.030841"/>
    </inertial>
    <visual>
      <origin rpy="0 0 0" xyz="0.104 0.214 -0.034907"/>
      <geometry>
        <mesh filename="package://quadurdf_description/meshes/ACTUATOR_V2__HIP__v3_4.stl" scale="0.001 0.001 0.001"/>
      </geometry>
      <material name="steel_satin"/>
    </visual>
    <collision>
      <origin rpy="0 0 0" xyz="0.104 0.214 -0.034907"/>
      <geometry>
        <mesh filename="package://quadurdf_description/meshes/ACTUATOR_V2__HIP__v3_4.stl" scale="0.001 0.001 0.001"/>
      </geometry>
    </collision>
  </link>
  <link name="ACTUATOR_V2__HIP__v3_2">
    <inertial>
      <origin rpy="0 0 0" xyz="0.03826833790951979 -0.002331441161630504 -0.03491102872216063"/>
      <mass value="5.047347679862185"/>
      <inertia ixx="0.004708" ixy="0.003872" ixz="-1e-06" iyy="0.030025" iyz="-1e-06" izz="0.030841"/>
    </inertial>
    <visual>
      <origin rpy="0 0 0" xyz="-0.029 0.214 -0.034907"/>
      <geometry>
        <mesh filename="package://quadurdf_description/meshes/ACTUATOR_V2__HIP__v3_2.stl" scale="0.001 0.001 0.001"/>
      </geometry>
      <material name="steel_satin"/>
    </visual>
    <collision>
      <origin rpy="0 0 0" xyz="-0.029 0.214 -0.034907"/>
      <geometry>
        <mesh filename="package://quadurdf_description/meshes/ACTUATOR_V2__HIP__v3_2.stl" scale="0.001 0.001 0.001"/>
      </geometry>
    </collision>
  </link>
  <link name="ACTUATOR_V2__KNEE__v6_1">
    <inertial>
      <origin rpy="0 0 0" xyz="-0.06890901958647971 0.060950499903433694 -3.6581764482816987e-06"/>
      <mass value="5.558605976842633"/>
      <inertia ixx="0.005451" ixy="0.003973" ixz="1e-06" iyy="0.034132" iyz="1e-06" izz="0.0346"/>
    </inertial>
    <visual>
      <origin rpy="0 0 0" xyz="-0.17587 0.0432 -0.0"/>
      <geometry>
        <mesh filename="package://quadurdf_description/meshes/ACTUATOR_V2__KNEE__v6_1.stl" scale="0.001 0.001 0.001"/>
      </geometry>
      <material name="steel_satin"/>
    </visual>
    <collision>
      <origin rpy="0 0 0" xyz="-0.17587 0.0432 -0.0"/>
      <geometry>
        <mesh filename="package://quadurdf_description/meshes/ACTUATOR_V2__KNEE__v6_1.stl" scale="0.001 0.001 0.001"/>
      </geometry>
    </collision>
  </link>
  <link name="ACTUATOR_V2__KNEE__v6_2">
    <inertial>
      <origin rpy="0 0 0" xyz="-0.06890901958647971 -0.06095049990342971 3.6581764448034913e-06"/>
      <mass value="5.558605976842633"/>
      <inertia ixx="0.005451" ixy="-0.003973" ixz="-1e-06" iyy="0.034132" iyz="1e-06" izz="0.0346"/>
    </inertial>
    <visual>
      <origin rpy="0 0 0" xyz="-0.17587 0.253 -0.0"/>
      <geometry>
        <mesh filename="package://quadurdf_description/meshes/ACTUATOR_V2__KNEE__v6_2.stl" scale="0.001 0.001 0.001"/>
      </geometry>
      <material name="steel_satin"/>
    </visual>
    <collision>
      <origin rpy="0 0 0" xyz="-0.17587 0.253 -0.0"/>
      <geometry>
        <mesh filename="package://quadurdf_description/meshes/ACTUATOR_V2__KNEE__v6_2.stl" scale="0.001 0.001 0.001"/>
      </geometry>
    </collision>
  </link>
  <link name="ACTUATOR_V2__KNEE__v6_3">
    <inertial>
      <origin rpy="0 0 0" xyz="0.06890901958647999 -0.06095049990342977 -3.6581764461465336e-06"/>
      <mass value="5.558605976842633"/>
      <inertia ixx="0.005451" ixy="0.003973" ixz="-1e-06" iyy="0.034132" iyz="-1e-06" izz="0.0346"/>
    </inertial>
    <visual>
      <origin rpy="0 0 0" xyz="0.25087 0.253 -0.0"/>
      <geometry>
        <mesh filename="package://quadurdf_description/meshes/ACTUATOR_V2__KNEE__v6_3.stl" scale="0.001 0.001 0.001"/>
      </geometry>
      <material name="steel_satin"/>
    </visual>
    <collision>
      <origin rpy="0 0 0" xyz="0.25087 0.253 -0.0"/>
      <geometry>
        <mesh filename="package://quadurdf_description/meshes/ACTUATOR_V2__KNEE__v6_3.stl" scale="0.001 0.001 0.001"/>
      </geometry>
    </collision>
  </link>
  <link name="ACTUATOR_V2__KNEE__v6_4">
    <inertial>
      <origin rpy="0 0 0" xyz="0.06890901958647933 0.06095049990342992 3.6581764397704956e-06"/>
      <mass value="5.558605976842633"/>
      <inertia ixx="0.005451" ixy="-0.003973" ixz="1e-06" iyy="0.034132" iyz="-1e-06" izz="0.0346"/>
    </inertial>
    <visual>
      <origin rpy="0 0 0" xyz="0.25087 0.0432 -0.0"/>
      <geometry>
        <mesh filename="package://quadurdf_description/meshes/ACTUATOR_V2__KNEE__v6_4.stl" scale="0.001 0.001 0.001"/>
      </geometry>
      <material name="steel_satin"/>
    </visual>
    <collision>
      <origin rpy="0 0 0" xyz="0.25087 0.0432 -0.0"/>
      <geometry>
        <mesh filename="package://quadurdf_description/meshes/ACTUATOR_V2__KNEE__v6_4.stl" scale="0.001 0.001 0.001"/>
      </geometry>
    </collision>
  </link>
  <link name="ANKLE_v3_1">
    <inertial>
      <origin rpy="0 0 0" xyz="0.056464507580721114 -0.02164768809099279 -0.03953688108935136"/>
      <mass value="0.9257706970730075"/>
      <inertia ixx="0.000905" ixy="5.5e-05" ixz="0.001139" iyy="0.002526" iyz="-3.9e-05" izz="0.001734"/>
    </inertial>
    <visual>
      <origin rpy="0 0 0" xyz="0.0 0.0027 0.0"/>
      <geometry>
        <mesh filename="package://quadurdf_description/meshes/ANKLE_v3_1.stl" scale="0.001 0.001 0.001"/>
      </geometry>
      <material name="steel_satin"/>
    </visual>
    <collision>
      <origin rpy="0 0 0" xyz="0.0 0.0027 0.0"/>
      <geometry>
        <mesh filename="package://quadurdf_description/meshes/ANKLE_v3_1.stl" scale="0.001 0.001 0.001"/>
      </geometry>
    </collision>
  </link>
  <link name="ANKLE_v3_2">
    <inertial>
      <origin rpy="0 0 0" xyz="0.056464514384120416 0.02164768809099804 -0.039536871373086875"/>
      <mass value="0.9257706970730075"/>
      <inertia ixx="0.000905" ixy="-5.5e-05" ixz="0.001139" iyy="0.002526" iyz="3.9e-05" izz="0.001734"/>
    </inertial>
    <visual>
      <origin rpy="0 0 0" xyz="0.0 0.2935 0.0"/>
      <geometry>
        <mesh filename="package://quadurdf_description/meshes/ANKLE_v3_2.stl" scale="0.001 0.001 0.001"/>
      </geometry>
      <material name="steel_satin"/>
    </visual>
    <collision>
      <origin rpy="0 0 0" xyz="0.0 0.2935 0.0"/>
      <geometry>
        <mesh filename="package://quadurdf_description/meshes/ANKLE_v3_2.stl" scale="0.001 0.001 0.001"/>
      </geometry>
    </collision>
  </link>
  <link name="ANKLE_v3_3">
    <inertial>
      <origin rpy="0 0 0" xyz="-0.05646451438412105 -0.021647688090997524 -0.03953687137309259"/>
      <mass value="0.9257706970730075"/>
      <inertia ixx="0.000905" ixy="-5.5e-05" ixz="-0.001139" iyy="0.002526" iyz="-3.9e-05" izz="0.001734"/>
    </inertial>
    <visual>
      <origin rpy="0 0 0" xyz="0.075 0.0027 0.0"/>
      <geometry>
        <mesh filename="package://quadurdf_description/meshes/ANKLE_v3_3.stl" scale="0.001 0.001 0.001"/>
      </geometry>
      <material name="steel_satin"/>
    </visual>
    <collision>
      <origin rpy="0 0 0" xyz="0.075 0.0027 0.0"/>
      <geometry>
        <mesh filename="package://quadurdf_description/meshes/ANKLE_v3_3.stl" scale="0.001 0.001 0.001"/>
      </geometry>
    </collision>
  </link>
  <link name="ANKLE_v3_4">
    <inertial>
      <origin rpy="0 0 0" xyz="-0.05646450758072004 0.021647688090999317 -0.03953688108934738"/>
      <mass value="0.9257706970730075"/>
      <inertia ixx="0.000905" ixy="5.5e-05" ixz="-0.001139" iyy="0.002526" iyz="3.9e-05" izz="0.001734"/>
    </inertial>
    <visual>
      <origin rpy="0 0 0" xyz="0.075 0.2935 -0.0"/>
      <geometry>
        <mesh filename="package://quadurdf_description/meshes/ANKLE_v3_4.stl" scale="0.001 0.001 0.001"/>
      </geometry>
      <material name="steel_satin"/>
    </visual>
    <collision>
      <origin rpy="0 0 0" xyz="0.075 0.2935 -0.0"/>
      <geometry>
        <mesh filename="package://quadurdf_description/meshes/ANKLE_v3_4.stl" scale="0.001 0.001 0.001"/>
      </geometry>
    </collision>
  </link>
  <link name="6200_MAH_BATTERY_v1_1">
    <inertial>
      <origin rpy="0 0 0" xyz="6.245004513516506e-17 1.2212453270876722e-15 -0.024000499999997683"/>
      <mass value="2.7777696"/>
      <inertia ixx="0.001078" ixy="0.0" ixz="0.0" iyy="0.005881" iyz="-0.0" izz="0.005893"/>
    </inertial>
    <visual>
      <origin rpy="0 0 0" xyz="0.0375 0.1481 -0.034907"/>
      <geometry>
        <mesh filename="package://quadurdf_description/meshes/6200_MAH_BATTERY_v1_1.stl" scale="0.001 0.001 0.001"/>
      </geometry>
      <material name="steel_satin"/>
    </visual>
    <collision>
      <origin rpy="0 0 0" xyz="0.0375 0.1481 -0.034907"/>
      <geometry>
        <mesh filename="package://quadurdf_description/meshes/6200_MAH_BATTERY_v1_1.stl" scale="0.001 0.001 0.001"/>
      </geometry>
    </collision>
  </link>
  <joint name="Rigid 1" type="fixed">
    <origin rpy="0 0 0" xyz="-0.104 -0.0822 0.034907"/>
    <parent link="base_link"/>
    <child link="ACTUATOR_V2__HIP__v3_3"/>
  </joint>
  <joint name="Rigid 2" type="fixed">
    <origin rpy="0 0 0" xyz="0.029 -0.0522 0.034907"/>
    <parent link="base_link"/>
    <child link="ACTUATOR_V2__HIP__v3_1"/>
  </joint>
  <joint name="Rigid 3" type="fixed">
    <origin rpy="0 0 0" xyz="-0.104 -0.214 0.034907"/>
    <parent link="base_link"/>
    <child link="ACTUATOR_V2__HIP__v3_4"/>
  </joint>
  <joint name="Rigid 4" type="fixed">
    <origin rpy="0 0 0" xyz="0.029 -0.214 0.034907"/>
    <parent link="base_link"/>
    <child link="ACTUATOR_V2__HIP__v3_2"/>
  </joint>
  <joint name="11" type="continuous">
    <origin rpy="0 0 0" xyz="0.14687 0.009 -0.034907"/>
    <parent link="ACTUATOR_V2__HIP__v3_1"/>
    <child link="ACTUATOR_V2__KNEE__v6_1"/>
    <axis xyz="0.0 -1.0 -0.0"/>
  </joint>
  <joint name="21" type="continuous">
    <origin rpy="0 0 0" xyz="0.14687 -0.039 -0.034907"/>
    <parent link="ACTUATOR_V2__HIP__v3_2"/>
    <child link="ACTUATOR_V2__KNEE__v6_2"/>
    <axis xyz="0.0 1.0 0.0"/>
  </joint>
  <joint name="41" type="continuous">
    <origin rpy="0 0 0" xyz="-0.14687 -0.039 -0.034907"/>
    <parent link="ACTUATOR_V2__HIP__v3_4"/>
    <child link="ACTUATOR_V2__KNEE__v6_3"/>
    <axis xyz="-0.0 1.0 0.0"/>
  </joint>
  <joint name="31" type="continuous">
    <origin rpy="0 0 0" xyz="-0.14687 0.039 -0.034907"/>
    <parent link="ACTUATOR_V2__HIP__v3_3"/>
    <child link="ACTUATOR_V2__KNEE__v6_4"/>
    <axis xyz="-0.0 -1.0 -0.0"/>
  </joint>
  <joint name="12" type="continuous">
    <origin rpy="0 0 0" xyz="-0.17587 0.0405 -0.0"/>
    <parent link="ACTUATOR_V2__KNEE__v6_1"/>
    <child link="ANKLE_v3_1"/>
    <axis xyz="-0.0 -1.0 -0.0"/>
  </joint>
  <joint name="22" type="continuous">
    <origin rpy="0 0 0" xyz="-0.17587 -0.0405 -0.0"/>
    <parent link="ACTUATOR_V2__KNEE__v6_2"/>
    <child link="ANKLE_v3_2"/>
    <axis xyz="0.0 -1.0 -0.0"/>
  </joint>
  <joint name="32" type="continuous">
    <origin rpy="0 0 0" xyz="0.17587 0.0405 -0.0"/>
    <parent link="ACTUATOR_V2__KNEE__v6_4"/>
    <child link="ANKLE_v3_3"/>
    <axis xyz="-0.0 1.0 -0.0"/>
  </joint>
  <joint name="42" type="continuous">
    <origin rpy="0 0 0" xyz="0.17587 -0.0405 0.0"/>
    <parent link="ACTUATOR_V2__KNEE__v6_3"/>
    <child link="ANKLE_v3_4"/>
    <axis xyz="-0.0 -1.0 -0.0"/>
  </joint>
  <joint name="Rigid 13" type="fixed">
    <origin rpy="0 0 0" xyz="-0.0375 -0.1481 0.034907"/>
    <parent link="base_link"/>
    <child link="6200_MAH_BATTERY_v1_1"/>
  </joint>
</robot>
