<?xml version="1.0" ?>
<!-- =================================================================================== -->
<!-- |    This document was autogenerated by xacro from .\urdf\mistletoe.xacro         | -->
<!-- |    EDITING THIS FILE BY HAND IS NOT RECOMMENDED                                 | -->
<!-- =================================================================================== -->
<robot xmlns:xacro="http://www.ros.org/wiki/xacro" name="mistletoe">
  <material name="silver_default">
    <color rgba="0.700 0.700 0.700 1.000"/>
  </material>
  <material name="plastic_glossy_black">
    <color rgba="0.09803921568627451 0.09803921568627451 0.09803921568627451 1.0"/>
  </material>
  <transmission name="Revolute 11_tran">
    <type>transmission_interface/SimpleTransmission</type>
    <joint name="Revolute 11">
      <hardwareInterface>hardware_interface/EffortJointInterface</hardwareInterface>
    </joint>
    <actuator name="Revolute 11_actr">
      <hardwareInterface>hardware_interface/EffortJointInterface</hardwareInterface>
      <mechanicalReduction>1</mechanicalReduction>
    </actuator>
  </transmission>
  <transmission name="Revolute 12_tran">
    <type>transmission_interface/SimpleTransmission</type>
    <joint name="Revolute 12">
      <hardwareInterface>hardware_interface/EffortJointInterface</hardwareInterface>
    </joint>
    <actuator name="Revolute 12_actr">
      <hardwareInterface>hardware_interface/EffortJointInterface</hardwareInterface>
      <mechanicalReduction>1</mechanicalReduction>
    </actuator>
  </transmission>
  <transmission name="Revolute 15_tran">
    <type>transmission_interface/SimpleTransmission</type>
    <joint name="Revolute 15">
      <hardwareInterface>hardware_interface/EffortJointInterface</hardwareInterface>
    </joint>
    <actuator name="Revolute 15_actr">
      <hardwareInterface>hardware_interface/EffortJointInterface</hardwareInterface>
      <mechanicalReduction>1</mechanicalReduction>
    </actuator>
  </transmission>
  <transmission name="Revolute 16_tran">
    <type>transmission_interface/SimpleTransmission</type>
    <joint name="Revolute 16">
      <hardwareInterface>hardware_interface/EffortJointInterface</hardwareInterface>
    </joint>
    <actuator name="Revolute 16_actr">
      <hardwareInterface>hardware_interface/EffortJointInterface</hardwareInterface>
      <mechanicalReduction>1</mechanicalReduction>
    </actuator>
  </transmission>
  <transmission name="Revolute 17_tran">
    <type>transmission_interface/SimpleTransmission</type>
    <joint name="Revolute 17">
      <hardwareInterface>hardware_interface/EffortJointInterface</hardwareInterface>
    </joint>
    <actuator name="Revolute 17_actr">
      <hardwareInterface>hardware_interface/EffortJointInterface</hardwareInterface>
      <mechanicalReduction>1</mechanicalReduction>
    </actuator>
  </transmission>
  <transmission name="Revolute 18_tran">
    <type>transmission_interface/SimpleTransmission</type>
    <joint name="Revolute 18">
      <hardwareInterface>hardware_interface/EffortJointInterface</hardwareInterface>
    </joint>
    <actuator name="Revolute 18_actr">
      <hardwareInterface>hardware_interface/EffortJointInterface</hardwareInterface>
      <mechanicalReduction>1</mechanicalReduction>
    </actuator>
  </transmission>
  <transmission name="Revolute 20_tran">
    <type>transmission_interface/SimpleTransmission</type>
    <joint name="Revolute 20">
      <hardwareInterface>hardware_interface/EffortJointInterface</hardwareInterface>
    </joint>
    <actuator name="Revolute 20_actr">
      <hardwareInterface>hardware_interface/EffortJointInterface</hardwareInterface>
      <mechanicalReduction>1</mechanicalReduction>
    </actuator>
  </transmission>
  <transmission name="Revolute 21_tran">
    <type>transmission_interface/SimpleTransmission</type>
    <joint name="Revolute 21">
      <hardwareInterface>hardware_interface/EffortJointInterface</hardwareInterface>
    </joint>
    <actuator name="Revolute 21_actr">
      <hardwareInterface>hardware_interface/EffortJointInterface</hardwareInterface>
      <mechanicalReduction>1</mechanicalReduction>
    </actuator>
  </transmission>
  <transmission name="Revolute 22_tran">
    <type>transmission_interface/SimpleTransmission</type>
    <joint name="Revolute 22">
      <hardwareInterface>hardware_interface/EffortJointInterface</hardwareInterface>
    </joint>
    <actuator name="Revolute 22_actr">
      <hardwareInterface>hardware_interface/EffortJointInterface</hardwareInterface>
      <mechanicalReduction>1</mechanicalReduction>
    </actuator>
  </transmission>
  <transmission name="Revolute 23_tran">
    <type>transmission_interface/SimpleTransmission</type>
    <joint name="Revolute 23">
      <hardwareInterface>hardware_interface/EffortJointInterface</hardwareInterface>
    </joint>
    <actuator name="Revolute 23_actr">
      <hardwareInterface>hardware_interface/EffortJointInterface</hardwareInterface>
      <mechanicalReduction>1</mechanicalReduction>
    </actuator>
  </transmission>
  <transmission name="Revolute 24_tran">
    <type>transmission_interface/SimpleTransmission</type>
    <joint name="Revolute 24">
      <hardwareInterface>hardware_interface/EffortJointInterface</hardwareInterface>
    </joint>
    <actuator name="Revolute 24_actr">
      <hardwareInterface>hardware_interface/EffortJointInterface</hardwareInterface>
      <mechanicalReduction>1</mechanicalReduction>
    </actuator>
  </transmission>
  <transmission name="Revolute 25_tran">
    <type>transmission_interface/SimpleTransmission</type>
    <joint name="Revolute 25">
      <hardwareInterface>hardware_interface/EffortJointInterface</hardwareInterface>
    </joint>
    <actuator name="Revolute 25_actr">
      <hardwareInterface>hardware_interface/EffortJointInterface</hardwareInterface>
      <mechanicalReduction>1</mechanicalReduction>
    </actuator>
  </transmission>
  <link name="base_link">
    <inertial>
      <origin xyz="-0.06657859086794671 -0.12180227598730413 -0.027661254547312428" rpy="0 0 0"/>
      <mass value="2.781822888066483"/>
      <inertia ixx="0.012347" iyy="0.169247" izz="0.177361" ixy="3e-06" iyz="0.0" ixz="4.1e-05"/>
    </inertial>
    <visual>
      <origin xyz="0 0 0" rpy="0 0 0"/>
      <geometry>
        <mesh filename="package://mistletoe_description/meshes/base_link.stl" scale="0.001 0.001 0.001"/>
      </geometry>
      <material name="plastic_glossy_black"/>
    </visual>
    <collision>
      <origin xyz="0 0 0" rpy="0 0 0"/>
      <geometry>
        <mesh filename="package://mistletoe_description/meshes/base_link.stl" scale="0.001 0.001 0.001"/>
      </geometry>
    </collision>
  </link>
  <link name="ANKLE_v4_1">
    <inertial>
      <origin xyz="0.05969551525022495 -0.021647688090993697 0.03446521495096979" rpy="0 0 0"/>
      <mass value="0.0707595437253254"/>
      <inertia ixx="5.5e-05" iyy="0.000193" izz="0.000147" ixy="4e-06" iyz="3e-06" ixz="-8e-05"/>
    </inertial>
    <visual>
      <origin xyz="-0.002 -0.0695 0.025" rpy="0 0 0"/>
      <geometry>
        <mesh filename="package://mistletoe_description/meshes/ANKLE_v4_1.stl" scale="0.001 0.001 0.001"/>
      </geometry>
      <material name="plastic_glossy_black"/>
    </visual>
    <collision>
      <origin xyz="-0.002 -0.0695 0.025" rpy="0 0 0"/>
      <geometry>
        <mesh filename="package://mistletoe_description/meshes/ANKLE_v4_1.stl" scale="0.001 0.001 0.001"/>
      </geometry>
    </collision>
  </link>
  <link name="ACTUATOR_V2.1__KNEE__v10_1">
    <inertial>
      <origin xyz="-0.053095905532469054 0.060256502054564544 6.906335524137219e-06" rpy="0 0 0"/>
      <mass value="0.6687419456686833"/>
      <inertia ixx="0.000581" iyy="0.003897" izz="0.004059" ixy="0.000492" iyz="0.0" ixz="-0.0"/>
    </inertial>
    <visual>
      <origin xyz="-0.17787 -0.025 0.025" rpy="0 0 0"/>
      <geometry>
        <mesh filename="package://mistletoe_description/meshes/ACTUATOR_V2.1__KNEE__v10_1.stl" scale="0.001 0.001 0.001"/>
      </geometry>
      <material name="plastic_glossy_black"/>
    </visual>
    <collision>
      <origin xyz="-0.17787 -0.025 0.025" rpy="0 0 0"/>
      <geometry>
        <mesh filename="package://mistletoe_description/meshes/ACTUATOR_V2.1__KNEE__v10_1.stl" scale="0.001 0.001 0.001"/>
      </geometry>
    </collision>
  </link>
  <link name="Hip_1">
    <inertial>
      <origin xyz="-0.1675167715088863 -0.008238257074782445 5.1741322754095265e-09" rpy="0 0 0"/>
      <mass value="0.5600707780907046"/>
      <inertia ixx="0.000428" iyy="0.004847" izz="0.004917" ixy="-0.000319" iyz="-0.0" ixz="0.0"/>
    </inertial>
    <visual>
      <origin xyz="-0.255776 0.0 0.025" rpy="0 0 0"/>
      <geometry>
        <mesh filename="package://mistletoe_description/meshes/Hip_1.stl" scale="0.001 0.001 0.001"/>
      </geometry>
      <material name="plastic_glossy_black"/>
    </visual>
    <collision>
      <origin xyz="-0.255776 0.0 0.025" rpy="0 0 0"/>
      <geometry>
        <mesh filename="package://mistletoe_description/meshes/Hip_1.stl" scale="0.001 0.001 0.001"/>
      </geometry>
    </collision>
  </link>
  <link name="Hip_2">
    <inertial>
      <origin xyz="-0.1675167715088863 0.008238257074782346 -5.1741326362320095e-09" rpy="0 0 0"/>
      <mass value="0.5600707780907046"/>
      <inertia ixx="0.000428" iyy="0.004847" izz="0.004917" ixy="0.000319" iyz="-0.0" ixz="-0.0"/>
    </inertial>
    <visual>
      <origin xyz="-0.255776 0.243608 0.025" rpy="0 0 0"/>
      <geometry>
        <mesh filename="package://mistletoe_description/meshes/Hip_2.stl" scale="0.001 0.001 0.001"/>
      </geometry>
      <material name="plastic_glossy_black"/>
    </visual>
    <collision>
      <origin xyz="-0.255776 0.243608 0.025" rpy="0 0 0"/>
      <geometry>
        <mesh filename="package://mistletoe_description/meshes/Hip_2.stl" scale="0.001 0.001 0.001"/>
      </geometry>
    </collision>
  </link>
  <link name="ACTUATOR_V2.1__KNEE__v10_2">
    <inertial>
      <origin xyz="-0.05309590553246836 -0.06025650205456423 -6.906335525459079e-06" rpy="0 0 0"/>
      <mass value="0.6687419456686833"/>
      <inertia ixx="0.000581" iyy="0.003897" izz="0.004059" ixy="-0.000492" iyz="0.0" ixz="0.0"/>
    </inertial>
    <visual>
      <origin xyz="-0.17787 0.268608 0.025" rpy="0 0 0"/>
      <geometry>
        <mesh filename="package://mistletoe_description/meshes/ACTUATOR_V2.1__KNEE__v10_2.stl" scale="0.001 0.001 0.001"/>
      </geometry>
      <material name="plastic_glossy_black"/>
    </visual>
    <collision>
      <origin xyz="-0.17787 0.268608 0.025" rpy="0 0 0"/>
      <geometry>
        <mesh filename="package://mistletoe_description/meshes/ACTUATOR_V2.1__KNEE__v10_2.stl" scale="0.001 0.001 0.001"/>
      </geometry>
    </collision>
  </link>
  <link name="ANKLE_v4_2">
    <inertial>
      <origin xyz="0.05969550931954534 0.02164768809099249 0.034465225223213276" rpy="0 0 0"/>
      <mass value="0.0707595437253254"/>
      <inertia ixx="5.5e-05" iyy="0.000193" izz="0.000147" ixy="-4e-06" iyz="-3e-06" ixz="-8e-05"/>
    </inertial>
    <visual>
      <origin xyz="-0.002 0.313108 0.025" rpy="0 0 0"/>
      <geometry>
        <mesh filename="package://mistletoe_description/meshes/ANKLE_v4_2.stl" scale="0.001 0.001 0.001"/>
      </geometry>
      <material name="plastic_glossy_black"/>
    </visual>
    <collision>
      <origin xyz="-0.002 0.313108 0.025" rpy="0 0 0"/>
      <geometry>
        <mesh filename="package://mistletoe_description/meshes/ANKLE_v4_2.stl" scale="0.001 0.001 0.001"/>
      </geometry>
    </collision>
  </link>
  <link name="Hip_3">
    <inertial>
      <origin xyz="0.16751677150888733 -0.008238257074779353 -5.1741440437735875e-09" rpy="0 0 0"/>
      <mass value="0.5600707780907046"/>
      <inertia ixx="0.000428" iyy="0.004847" izz="0.004917" ixy="0.000319" iyz="0.0" ixz="0.0"/>
    </inertial>
    <visual>
      <origin xyz="0.389589 -0.0 0.025" rpy="0 0 0"/>
      <geometry>
        <mesh filename="package://mistletoe_description/meshes/Hip_3.stl" scale="0.001 0.001 0.001"/>
      </geometry>
      <material name="plastic_glossy_black"/>
    </visual>
    <collision>
      <origin xyz="0.389589 -0.0 0.025" rpy="0 0 0"/>
      <geometry>
        <mesh filename="package://mistletoe_description/meshes/Hip_3.stl" scale="0.001 0.001 0.001"/>
      </geometry>
    </collision>
  </link>
  <link name="Hip_4">
    <inertial>
      <origin xyz="0.16751677150888733 0.008238257074783567 5.174120378675928e-09" rpy="0 0 0"/>
      <mass value="0.5600707780907046"/>
      <inertia ixx="0.000428" iyy="0.004847" izz="0.004917" ixy="-0.000319" iyz="0.0" ixz="-0.0"/>
    </inertial>
    <visual>
      <origin xyz="0.389589 0.243608 0.025" rpy="0 0 0"/>
      <geometry>
        <mesh filename="package://mistletoe_description/meshes/Hip_4.stl" scale="0.001 0.001 0.001"/>
      </geometry>
      <material name="plastic_glossy_black"/>
    </visual>
    <collision>
      <origin xyz="0.389589 0.243608 0.025" rpy="0 0 0"/>
      <geometry>
        <mesh filename="package://mistletoe_description/meshes/Hip_4.stl" scale="0.001 0.001 0.001"/>
      </geometry>
    </collision>
  </link>
  <link name="ACTUATOR_V2.1__KNEE__v10_3">
    <inertial>
      <origin xyz="0.05309590553246918 0.06025650205456721 -6.906335536495389e-06" rpy="0 0 0"/>
      <mass value="0.6687419456686833"/>
      <inertia ixx="0.000581" iyy="0.003897" izz="0.004059" ixy="-0.000492" iyz="-0.0" ixz="-0.0"/>
    </inertial>
    <visual>
      <origin xyz="0.311683 -0.025 0.025" rpy="0 0 0"/>
      <geometry>
        <mesh filename="package://mistletoe_description/meshes/ACTUATOR_V2.1__KNEE__v10_3.stl" scale="0.001 0.001 0.001"/>
      </geometry>
      <material name="plastic_glossy_black"/>
    </visual>
    <collision>
      <origin xyz="0.311683 -0.025 0.025" rpy="0 0 0"/>
      <geometry>
        <mesh filename="package://mistletoe_description/meshes/ACTUATOR_V2.1__KNEE__v10_3.stl" scale="0.001 0.001 0.001"/>
      </geometry>
    </collision>
  </link>
  <link name="ACTUATOR_V2.1__KNEE__v10_4">
    <inertial>
      <origin xyz="0.05309590553246907 -0.060256502054563066 6.906335511820683e-06" rpy="0 0 0"/>
      <mass value="0.6687419456686833"/>
      <inertia ixx="0.000581" iyy="0.003897" izz="0.004059" ixy="0.000492" iyz="-0.0" ixz="0.0"/>
    </inertial>
    <visual>
      <origin xyz="0.311683 0.268608 0.025" rpy="0 0 0"/>
      <geometry>
        <mesh filename="package://mistletoe_description/meshes/ACTUATOR_V2.1__KNEE__v10_4.stl" scale="0.001 0.001 0.001"/>
      </geometry>
      <material name="plastic_glossy_black"/>
    </visual>
    <collision>
      <origin xyz="0.311683 0.268608 0.025" rpy="0 0 0"/>
      <geometry>
        <mesh filename="package://mistletoe_description/meshes/ACTUATOR_V2.1__KNEE__v10_4.stl" scale="0.001 0.001 0.001"/>
      </geometry>
    </collision>
  </link>
  <link name="ANKLE_v4_3">
    <inertial>
      <origin xyz="-0.059695515250226594 0.021647688090994432 0.03446521495095798" rpy="0 0 0"/>
      <mass value="0.0707595437253254"/>
      <inertia ixx="5.5e-05" iyy="0.000193" izz="0.000147" ixy="4e-06" iyz="-3e-06" ixz="8e-05"/>
    </inertial>
    <visual>
      <origin xyz="0.135813 0.313108 0.025" rpy="0 0 0"/>
      <geometry>
        <mesh filename="package://mistletoe_description/meshes/ANKLE_v4_3.stl" scale="0.001 0.001 0.001"/>
      </geometry>
      <material name="plastic_glossy_black"/>
    </visual>
    <collision>
      <origin xyz="0.135813 0.313108 0.025" rpy="0 0 0"/>
      <geometry>
        <mesh filename="package://mistletoe_description/meshes/ANKLE_v4_3.stl" scale="0.001 0.001 0.001"/>
      </geometry>
    </collision>
  </link>
  <link name="ANKLE_v4_4">
    <inertial>
      <origin xyz="-0.05969550931954573 -0.021647688090990137 0.03446522522320031" rpy="0 0 0"/>
      <mass value="0.0707595437253254"/>
      <inertia ixx="5.5e-05" iyy="0.000193" izz="0.000147" ixy="-4e-06" iyz="3e-06" ixz="8e-05"/>
    </inertial>
    <visual>
      <origin xyz="0.135813 -0.0695 0.025" rpy="0 0 0"/>
      <geometry>
        <mesh filename="package://mistletoe_description/meshes/ANKLE_v4_4.stl" scale="0.001 0.001 0.001"/>
      </geometry>
      <material name="plastic_glossy_black"/>
    </visual>
    <collision>
      <origin xyz="0.135813 -0.0695 0.025" rpy="0 0 0"/>
      <geometry>
        <mesh filename="package://mistletoe_description/meshes/ANKLE_v4_4.stl" scale="0.001 0.001 0.001"/>
      </geometry>
    </collision>
  </link>
  <joint name="Revolute 11" type="continuous">
    <origin xyz="-0.17587 0.0445 0.0" rpy="0 0 0"/>
    <parent link="ACTUATOR_V2.1__KNEE__v10_1"/>
    <child link="ANKLE_v4_1"/>
    <axis xyz="0.0 1.0 0.0"/>
  </joint>
  <joint name="Revolute 12" type="continuous">
    <origin xyz="-0.077906 0.025 0.0" rpy="0 0 0"/>
    <parent link="Hip_1"/>
    <child link="ACTUATOR_V2.1__KNEE__v10_1"/>
    <axis xyz="0.0 -1.0 0.0"/>
  </joint>
  <joint name="Revolute 15" type="continuous">
    <origin xyz="0.255776 0.0 -0.025" rpy="0 0 0"/>
    <parent link="base_link"/>
    <child link="Hip_1"/>
    <axis xyz="-1.0 -0.0 -0.0"/>
  </joint>
  <joint name="Revolute 16" type="continuous">
    <origin xyz="0.255776 -0.243608 -0.025" rpy="0 0 0"/>
    <parent link="base_link"/>
    <child link="Hip_2"/>
    <axis xyz="1.0 -0.0 0.0"/>
  </joint>
  <joint name="Revolute 17" type="continuous">
    <origin xyz="-0.077906 -0.025 0.0" rpy="0 0 0"/>
    <parent link="Hip_2"/>
    <child link="ACTUATOR_V2.1__KNEE__v10_2"/>
    <axis xyz="0.0 1.0 -0.0"/>
  </joint>
  <joint name="Revolute 18" type="continuous">
    <origin xyz="-0.17587 -0.0445 0.0" rpy="0 0 0"/>
    <parent link="ACTUATOR_V2.1__KNEE__v10_2"/>
    <child link="ANKLE_v4_2"/>
    <axis xyz="0.0 -1.0 0.0"/>
  </joint>
  <joint name="Revolute 20" type="continuous">
    <origin xyz="-0.389589 0.0 -0.025" rpy="0 0 0"/>
    <parent link="base_link"/>
    <child link="Hip_3"/>
    <axis xyz="1.0 -0.0 0.0"/>
  </joint>
  <joint name="Revolute 21" type="continuous">
    <origin xyz="-0.389589 -0.243608 -0.025" rpy="0 0 0"/>
    <parent link="base_link"/>
    <child link="Hip_4"/>
    <axis xyz="1.0 -0.0 0.0"/>
  </joint>
  <joint name="Revolute 22" type="continuous">
    <origin xyz="0.077906 0.025 0.0" rpy="0 0 0"/>
    <parent link="Hip_3"/>
    <child link="ACTUATOR_V2.1__KNEE__v10_3"/>
    <axis xyz="-0.0 -1.0 0.0"/>
  </joint>
  <joint name="Revolute 23" type="continuous">
    <origin xyz="0.077906 -0.025 0.0" rpy="0 0 0"/>
    <parent link="Hip_4"/>
    <child link="ACTUATOR_V2.1__KNEE__v10_4"/>
    <axis xyz="-0.0 1.0 0.0"/>
  </joint>
  <joint name="Revolute 24" type="continuous">
    <origin xyz="0.17587 -0.0445 0.0" rpy="0 0 0"/>
    <parent link="ACTUATOR_V2.1__KNEE__v10_4"/>
    <child link="ANKLE_v4_3"/>
    <axis xyz="-0.0 -1.0 -0.0"/>
  </joint>
  <joint name="Revolute 25" type="continuous">
    <origin xyz="0.17587 0.0445 0.0" rpy="0 0 0"/>
    <parent link="ACTUATOR_V2.1__KNEE__v10_3"/>
    <child link="ANKLE_v4_4"/>
    <axis xyz="-0.0 1.0 -0.0"/>
  </joint>
</robot>
